2020-11-06 10:49:58,685 [ERROR]- Internal Server Error: /login
Traceback (most recent call last):
  File "/home/avanik/projects/demo/myapp/views.py", line 49, in post
    u = User.objects.get(email=email)
  File "/home/avanik/env/lib/python3.6/site-packages/django/db/models/manager.py", line 82, in manager_method
    return getattr(self.get_queryset(), name)(*args, **kwargs)
  File "/home/avanik/env/lib/python3.6/site-packages/django/db/models/query.py", line 403, in get
    self.model._meta.object_name
myapp.models.DoesNotExist: User matching query does not exist.

During handling of the above exception, another exception occurred:

Traceback (most recent call last):
  File "/home/avanik/env/lib/python3.6/site-packages/django/core/handlers/exception.py", line 35, in inner
    response = get_response(request)
  File "/home/avanik/env/lib/python3.6/site-packages/django/core/handlers/base.py", line 128, in _get_response
    response = self.process_exception_by_middleware(e, request)
  File "/home/avanik/env/lib/python3.6/site-packages/django/core/handlers/base.py", line 126, in _get_response
    response = wrapped_callback(request, *callback_args, **callback_kwargs)
  File "/home/avanik/env/lib/python3.6/site-packages/django/views/generic/base.py", line 69, in view
    return self.dispatch(request, *args, **kwargs)
  File "/home/avanik/env/lib/python3.6/site-packages/django/views/generic/base.py", line 89, in dispatch
    return handler(request, *args, **kwargs)
  File "/home/avanik/projects/demo/myapp/views.py", line 59, in post
    return render(request, self.template_name, {'msg': mjessage})
NameError: name 'mjessage' is not defined
2020-11-06 11:01:07,429 [ERROR]- Internal Server Error: /registration
Traceback (most recent call last):
  File "/home/avanik/env/lib/python3.6/site-packages/django/core/handlers/exception.py", line 35, in inner
    response = get_response(request)
  File "/home/avanik/env/lib/python3.6/site-packages/django/core/handlers/base.py", line 128, in _get_response
    response = self.process_exception_by_middleware(e, request)
  File "/home/avanik/env/lib/python3.6/site-packages/django/core/handlers/base.py", line 126, in _get_response
    response = wrapped_callback(request, *callback_args, **callback_kwargs)
  File "/home/avanik/env/lib/python3.6/site-packages/django/views/generic/base.py", line 69, in view
    return self.dispatch(request, *args, **kwargs)
  File "/home/avanik/env/lib/python3.6/site-packages/django/utils/decorators.py", line 62, in _wrapper
    return bound_func(*args, **kwargs)
  File "/home/avanik/projects/demo/myapp/decorator.py", line 7, in wrap
    return view_func(request, args, *kwargs)
  File "/home/avanik/env/lib/python3.6/site-packages/django/utils/decorators.py", line 58, in bound_func
    return func.__get__(self, type(self))(*args2, **kwargs2)
  File "/home/avanik/env/lib/python3.6/site-packages/django/views/generic/base.py", line 89, in dispatch
    return handler(request, *args, **kwargs)
TypeError: post() takes 2 positional arguments but 3 were given
2020-11-06 11:01:34,882 [ERROR]- Internal Server Error: /registration
Traceback (most recent call last):
  File "/home/avanik/env/lib/python3.6/site-packages/django/core/handlers/exception.py", line 35, in inner
    response = get_response(request)
  File "/home/avanik/env/lib/python3.6/site-packages/django/core/handlers/base.py", line 128, in _get_response
    response = self.process_exception_by_middleware(e, request)
  File "/home/avanik/env/lib/python3.6/site-packages/django/core/handlers/base.py", line 126, in _get_response
    response = wrapped_callback(request, *callback_args, **callback_kwargs)
  File "/home/avanik/env/lib/python3.6/site-packages/django/views/generic/base.py", line 69, in view
    return self.dispatch(request, *args, **kwargs)
  File "/home/avanik/env/lib/python3.6/site-packages/django/utils/decorators.py", line 62, in _wrapper
    return bound_func(*args, **kwargs)
  File "/home/avanik/projects/demo/myapp/decorator.py", line 7, in wrap
    return view_func(request, args, *kwargs)
  File "/home/avanik/env/lib/python3.6/site-packages/django/utils/decorators.py", line 58, in bound_func
    return func.__get__(self, type(self))(*args2, **kwargs2)
  File "/home/avanik/env/lib/python3.6/site-packages/django/views/generic/base.py", line 89, in dispatch
    return handler(request, *args, **kwargs)
TypeError: post() takes 2 positional arguments but 3 were given
2020-11-06 11:06:09,508 [WARNING]- Not Found: /login/
2020-11-06 11:06:13,546 [WARNING]- Not Found: /login/
2020-11-06 11:19:14,512 [ERROR]- Internal Server Error: /logout
Traceback (most recent call last):
  File "/home/avanik/env/lib/python3.6/site-packages/django/core/handlers/exception.py", line 35, in inner
    response = get_response(request)
  File "/home/avanik/env/lib/python3.6/site-packages/django/core/handlers/base.py", line 128, in _get_response
    response = self.process_exception_by_middleware(e, request)
  File "/home/avanik/env/lib/python3.6/site-packages/django/core/handlers/base.py", line 126, in _get_response
    response = wrapped_callback(request, *callback_args, **callback_kwargs)
  File "/home/avanik/projects/demo/myapp/views.py", line 67, in logout
    print("===after===", request.session['user_login'])
  File "/home/avanik/env/lib/python3.6/site-packages/django/contrib/sessions/backends/base.py", line 55, in __getitem__
    return self._session[key]
KeyError: 'user_login'
2020-11-06 11:31:27,820 [ERROR]- Internal Server Error: /
Traceback (most recent call last):
  File "/home/avanik/env/lib/python3.6/site-packages/django/template/base.py", line 475, in parse
    compile_func = self.tags[command]
KeyError: 'in'

During handling of the above exception, another exception occurred:

Traceback (most recent call last):
  File "/home/avanik/env/lib/python3.6/site-packages/django/core/handlers/exception.py", line 35, in inner
    response = get_response(request)
  File "/home/avanik/env/lib/python3.6/site-packages/django/core/handlers/base.py", line 158, in _get_response
    response = self.process_exception_by_middleware(e, request)
  File "/home/avanik/env/lib/python3.6/site-packages/django/core/handlers/base.py", line 156, in _get_response
    response = response.render()
  File "/home/avanik/env/lib/python3.6/site-packages/django/template/response.py", line 106, in render
    self.content = self.rendered_content
  File "/home/avanik/env/lib/python3.6/site-packages/django/template/response.py", line 81, in rendered_content
    template = self.resolve_template(self.template_name)
  File "/home/avanik/env/lib/python3.6/site-packages/django/template/response.py", line 63, in resolve_template
    return select_template(template, using=self.using)
  File "/home/avanik/env/lib/python3.6/site-packages/django/template/loader.py", line 42, in select_template
    return engine.get_template(template_name)
  File "/home/avanik/env/lib/python3.6/site-packages/django/template/backends/django.py", line 34, in get_template
    return Template(self.engine.get_template(template_name), self)
  File "/home/avanik/env/lib/python3.6/site-packages/django/template/engine.py", line 144, in get_template
    template, origin = self.find_template(template_name)
  File "/home/avanik/env/lib/python3.6/site-packages/django/template/engine.py", line 126, in find_template
    template = loader.get_template(name, skip=skip)
  File "/home/avanik/env/lib/python3.6/site-packages/django/template/loaders/base.py", line 30, in get_template
    contents, origin, origin.template_name, self.engine,
  File "/home/avanik/env/lib/python3.6/site-packages/django/template/base.py", line 160, in __init__
    self.nodelist = self.compile_nodelist()
  File "/home/avanik/env/lib/python3.6/site-packages/django/template/base.py", line 198, in compile_nodelist
    return parser.parse()
  File "/home/avanik/env/lib/python3.6/site-packages/django/template/base.py", line 483, in parse
    raise self.error(token, e)
  File "/home/avanik/env/lib/python3.6/site-packages/django/template/base.py", line 481, in parse
    compiled_result = compile_func(self, token)
  File "/home/avanik/env/lib/python3.6/site-packages/django/template/loader_tags.py", line 290, in do_extends
    nodelist = parser.parse()
  File "/home/avanik/env/lib/python3.6/site-packages/django/template/base.py", line 483, in parse
    raise self.error(token, e)
  File "/home/avanik/env/lib/python3.6/site-packages/django/template/base.py", line 481, in parse
    compiled_result = compile_func(self, token)
  File "/home/avanik/env/lib/python3.6/site-packages/django/template/loader_tags.py", line 233, in do_block
    nodelist = parser.parse(('endblock',))
  File "/home/avanik/env/lib/python3.6/site-packages/django/template/base.py", line 477, in parse
    self.invalid_block_tag(token, command, parse_until)
  File "/home/avanik/env/lib/python3.6/site-packages/django/template/base.py", line 533, in invalid_block_tag
    get_text_list(["'%s'" % p for p in parse_until], 'or'),
django.template.exceptions.TemplateSyntaxError: Invalid block tag on line 4: 'in', expected 'endblock'. Did you forget to register or load this tag?
